<?xml version="1.0" encoding="utf-8"?>
<!-- This URDF was automatically created by SolidWorks to URDF Exporter! Originally created by Stephen Brawner (brawner@gmail.com) 
     Commit Version: 1.6.0-4-g7f85cfe  Build Version: 1.6.7995.38578
     For more information, please see http://wiki.ros.org/sw_urdf_exporter -->
<robot
  name="URDF1">
  <link
    name="base_link">
    <inertial>
      <origin
        xyz="7.99044164168095E-12 7.813305558102E-12 0.0818008501965235"
        rpy="0 0 0" />
      <mass
        value="2.13452082267233" />
      <inertia
        ixx="0.0050502312439203"
        ixy="-8.75493254800235E-18"
        ixz="2.37831542367762E-10"
        iyy="0.0050502312439203"
        iyz="-2.37832832591156E-10"
        izz="0.0100179487101872" />
    </inertial>
    <visual>
      <origin
        xyz="0 0 0"
        rpy="0 0 0" />
      <geometry>
        <mesh
          filename="package://URDF1/meshes/base_link.STL" />
      </geometry>
      <material
        name="">
        <color
          rgba="0.898039215686275 0.917647058823529 0.929411764705882 1" />
      </material>
    </visual>
    <collision>
      <origin
        xyz="0 0 0"
        rpy="0 0 0" />
      <geometry>
        <mesh
          filename="package://URDF1/meshes/base_link.STL" />
      </geometry>
    </collision>
  </link>
  <link
    name="steer1">
    <inertial>
      <origin
        xyz="0.178060549462322 0.165756332600186 0.0457933558705709"
        rpy="0 0 0" />
      <mass
        value="1.11187721790204" />
      <inertia
        ixx="0.00063155394869454"
        ixy="-1.13006471159313E-06"
        ixz="-4.35955123828893E-08"
        iyy="0.000512034696539605"
        iyz="-6.30645396553421E-07"
        izz="0.000793052092005293" />
    </inertial>
    <visual>
      <origin
        xyz="0 0 0"
        rpy="0 0 0" />
      <geometry>
        <mesh
          filename="package://URDF1/meshes/steer1.STL" />
      </geometry>
      <material
        name="">
        <color
          rgba="1 1 1 0.35" />
      </material>
    </visual>
    <collision>
      <origin
        xyz="0 0 0"
        rpy="0 0 0" />
      <geometry>
        <mesh
          filename="package://URDF1/meshes/steer1.STL" />
      </geometry>
    </collision>
  </link>
  <joint
    name="steer1_joint"
    type="revolute">
    <origin
      xyz="0 0 0"
      rpy="0 0 0" />
    <parent
      link="base_link" />
    <child
      link="steer1" />
    <axis
      xyz="0 0 1" />
    <limit
      lower="0"
      upper="0"
      effort="14"
      velocity="40" />
  </joint>
  <link
    name="drive1">
    <inertial>
      <origin
        xyz="-1.91334036542257E-06 -1.16368720215476E-12 0.0665873390347005"
        rpy="0 0 0" />
      <mass
        value="0.0930124941569098" />
      <inertia
        ixx="5.68163374829909E-05"
        ixy="2.29427788018845E-14"
        ixz="3.67739908555925E-09"
        iyy="5.66303681063407E-05"
        iyz="8.78167686924925E-14"
        izz="8.81040187329367E-05" />
    </inertial>
    <visual>
      <origin
        xyz="0 0 0"
        rpy="0 0 0" />
      <geometry>
        <mesh
          filename="package://URDF1/meshes/drive1.STL" />
      </geometry>
      <material
        name="">
        <color
          rgba="1 1 1 0.35" />
      </material>
    </visual>
    <collision>
      <origin
        xyz="0 0 0"
        rpy="0 0 0" />
      <geometry>
        <mesh
          filename="package://URDF1/meshes/drive1.STL" />
      </geometry>
    </collision>
  </link>
  <joint
    name="drive1_joint"
    type="continuous">
    <origin
      xyz="0.178845190032161 0.124306651679894 0.0400000000000008"
      rpy="-1.5707963267949 0 0.0157397566307821" />
    <parent
      link="steer1" />
    <child
      link="drive1" />
    <axis
      xyz="0 0 -1" />
    <limit
      effort="4.5"
      velocity="52" />
  </joint>
  <link
    name="steer2">
    <inertial>
      <origin
        xyz="0.165756332600184 -0.178060549462328 0.0457933558705709"
        rpy="0 0 0" />
      <mass
        value="1.11187721790204" />
      <inertia
        ixx="0.000512034696539606"
        ixy="1.13006471159242E-06"
        ixz="-6.30645396553465E-07"
        iyy="0.00063155394869454"
        iyz="4.35955123828255E-08"
        izz="0.000793052092005293" />
    </inertial>
    <visual>
      <origin
        xyz="0 0 0"
        rpy="0 0 0" />
      <geometry>
        <mesh
          filename="package://URDF1/meshes/steer2.STL" />
      </geometry>
      <material
        name="">
        <color
          rgba="1 1 1 0.35" />
      </material>
    </visual>
    <collision>
      <origin
        xyz="0 0 0"
        rpy="0 0 0" />
      <geometry>
        <mesh
          filename="package://URDF1/meshes/steer2.STL" />
      </geometry>
    </collision>
  </link>
  <joint
    name="steer2_joint"
    type="revolute">
    <origin
      xyz="0 0 0"
      rpy="0 0 0" />
    <parent
      link="base_link" />
    <child
      link="steer2" />
    <axis
      xyz="0 0 1" />
    <limit
      lower="0"
      upper="0"
      effort="14"
      velocity="40" />
  </joint>
  <link
    name="drive2">
    <inertial>
      <origin
        xyz="-1.91334036536706E-06 -1.16369414104867E-12 0.0665873390347005"
        rpy="0 0 0" />
      <mass
        value="0.0930124941569098" />
      <inertia
        ixx="5.68163374829909E-05"
        ixy="2.29427789391726E-14"
        ixz="3.67739908556561E-09"
        iyy="5.66303681063408E-05"
        iyz="8.78167731038516E-14"
        izz="8.81040187329368E-05" />
    </inertial>
    <visual>
      <origin
        xyz="0 0 0"
        rpy="0 0 0" />
      <geometry>
        <mesh
          filename="package://URDF1/meshes/drive2.STL" />
      </geometry>
      <material
        name="">
        <color
          rgba="1 1 1 0.35" />
      </material>
    </visual>
    <collision>
      <origin
        xyz="0 0 0"
        rpy="0 0 0" />
      <geometry>
        <mesh
          filename="package://URDF1/meshes/drive2.STL" />
      </geometry>
    </collision>
  </link>
  <joint
    name="drive2_joint"
    type="continuous">
    <origin
      xyz="0.124306651679891 -0.178845190032167 0.0400000000000008"
      rpy="-1.5707963267949 0 -1.55505657016411" />
    <parent
      link="steer2" />
    <child
      link="drive2" />
    <axis
      xyz="0 0 -1" />
    <limit
      effort="4.5"
      velocity="52" />
  </joint>
  <link
    name="steer3">
    <inertial>
      <origin
        xyz="-0.178060549462328 -0.165756332600191 0.0457933558705708"
        rpy="0 0 0" />
      <mass
        value="1.11187721790204" />
      <inertia
        ixx="0.00063155394869454"
        ixy="-1.13006471159151E-06"
        ixz="4.35955123828394E-08"
        iyy="0.000512034696539605"
        iyz="6.30645396553404E-07"
        izz="0.000793052092005293" />
    </inertial>
    <visual>
      <origin
        xyz="0 0 0"
        rpy="0 0 0" />
      <geometry>
        <mesh
          filename="package://URDF1/meshes/steer3.STL" />
      </geometry>
      <material
        name="">
        <color
          rgba="1 1 1 0.35" />
      </material>
    </visual>
    <collision>
      <origin
        xyz="0 0 0"
        rpy="0 0 0" />
      <geometry>
        <mesh
          filename="package://URDF1/meshes/steer3.STL" />
      </geometry>
    </collision>
  </link>
  <joint
    name="steer3_joint"
    type="revolute">
    <origin
      xyz="0 0 0"
      rpy="0 0 0" />
    <parent
      link="base_link" />
    <child
      link="steer3" />
    <axis
      xyz="0 0 1" />
    <limit
      lower="0"
      upper="0"
      effort="14"
      velocity="40" />
  </joint>
  <link
    name="drive3">
    <inertial>
      <origin
        xyz="-1.9133403654642E-06 -1.16368373270781E-12 0.0665873390347004"
        rpy="0 0 0" />
      <mass
        value="0.0930124941569103" />
      <inertia
        ixx="5.68163374829912E-05"
        ixy="2.29427784146748E-14"
        ixz="3.67739908557805E-09"
        iyy="5.66303681063411E-05"
        iyz="8.78167678980971E-14"
        izz="8.81040187329372E-05" />
    </inertial>
    <visual>
      <origin
        xyz="0 0 0"
        rpy="0 0 0" />
      <geometry>
        <mesh
          filename="package://URDF1/meshes/drive3.STL" />
      </geometry>
      <material
        name="">
        <color
          rgba="1 1 1 0.35" />
      </material>
    </visual>
    <collision>
      <origin
        xyz="0 0 0"
        rpy="0 0 0" />
      <geometry>
        <mesh
          filename="package://URDF1/meshes/drive3.STL" />
      </geometry>
    </collision>
  </link>
  <joint
    name="drive3_joint"
    type="continuous">
    <origin
      xyz="-0.17885 -0.12431 0.04"
      rpy="-1.5708 0 -3.1259" />
    <parent
      link="steer3" />
    <child
      link="drive3" />
    <axis
      xyz="0 0 -1" />
    <limit
      effort="4.5"
      velocity="52" />
  </joint>
  <link
    name="steer4">
    <inertial>
      <origin
        xyz="-0.165756332600194 0.178060549462324 0.0457933558705709"
        rpy="0 0 0" />
      <mass
        value="1.11187721790204" />
      <inertia
        ixx="0.000512034696539606"
        ixy="1.13006471159155E-06"
        ixz="6.30645396553386E-07"
        iyy="0.00063155394869454"
        iyz="-4.35955123828805E-08"
        izz="0.000793052092005293" />
    </inertial>
    <visual>
      <origin
        xyz="0 0 0"
        rpy="0 0 0" />
      <geometry>
        <mesh
          filename="package://URDF1/meshes/steer4.STL" />
      </geometry>
      <material
        name="">
        <color
          rgba="1 1 1 0.35" />
      </material>
    </visual>
    <collision>
      <origin
        xyz="0 0 0"
        rpy="0 0 0" />
      <geometry>
        <mesh
          filename="package://URDF1/meshes/steer4.STL" />
      </geometry>
    </collision>
  </link>
  <joint
    name="steer4_joint"
    type="revolute">
    <origin
      xyz="0 0 0"
      rpy="0 0 0" />
    <parent
      link="base_link" />
    <child
      link="steer4" />
    <axis
      xyz="0 0 1" />
    <limit
      lower="0"
      upper="0"
      effort="14"
      velocity="40" />
  </joint>
  <link
    name="drive4">
    <inertial>
      <origin
        xyz="-1.91334036547808E-06 -1.16369414104867E-12 0.0665873390347006"
        rpy="0 0 0" />
      <mass
        value="0.0930124941569098" />
      <inertia
        ixx="5.68163374829909E-05"
        ixy="2.29427786411801E-14"
        ixz="3.67739908557725E-09"
        iyy="5.66303681063408E-05"
        iyz="8.78167722007216E-14"
        izz="8.81040187329367E-05" />
    </inertial>
    <visual>
      <origin
        xyz="0 0 0"
        rpy="0 0 0" />
      <geometry>
        <mesh
          filename="package://URDF1/meshes/drive4.STL" />
      </geometry>
      <material
        name="">
        <color
          rgba="1 1 1 0.35" />
      </material>
    </visual>
    <collision>
      <origin
        xyz="0 0 0"
        rpy="0 0 0" />
      <geometry>
        <mesh
          filename="package://URDF1/meshes/drive4.STL" />
      </geometry>
    </collision>
  </link>
  <joint
    name="drive4_joint"
    type="continuous">
    <origin
      xyz="-0.12431 0.17885 0.04"
      rpy="-1.5708 0 1.5865" />
    <parent
      link="steer4" />
    <child
      link="drive4" />
    <axis
      xyz="0 0 -1" />
    <limit
      effort="4.5"
      velocity="52" />
  </joint>
</robot>